Workbook

Sheet dataset_prodejny_nabytek
A1: ID | B1: Datum | C1: Prodejna | D1: Produkt | E1: Pocet_kusu | F1: Cena_za_kus | G1: Celkovy_prodej | H1: Zisk | I1: E-shop | J1: Doba_dodani | K1: Reklamace | L1: Spokojenost | M1: Typ_zakaznika | N1: dummy_eshop | O1: dummy_reklamace
A2: 230 | B2: 45403 | C2: Praha | D2: Pohovka Luxusní | E2: 14 | F2: 25000 | G2: 350000 | H2: 103979 | I2: ano | J2: 5 | K2: ne | L2: 3 | M2: individuální | N2: =IF(Tabulka1[[#This Row],[E-shop]]="ano",1,0) -> 1 | O2: =IF(Tabulka1[[#This Row],[Reklamace]]="ano",1,0) -> 0
A3: 345 | B3: 45469 | C3: Plzeň | D3: Pohovka Luxusní | E3: 14 | F3: 25000 | G3: 350000 | H3: 85573 | I3: ne | J3: 8 | K3: ano | L3: 1 | M3: individuální | N3: =IF(Tabulka1[[#This Row],[E-shop]]="ano",1,0) -> 0 | O3: =IF(Tabulka1[[#This Row],[Reklamace]]="ano",1,0) -> 1
A4: 483 | B4: 45677 | C4: Brno | D4: Pohovka Luxusní | E4: 14 | F4: 25000 | G4: 350000 | H4: 69599 | I4: ne | J4: 8 | K4: ano | L4: 2 | M4: individuální | N4: =IF(Tabulka1[[#This Row],[E-shop]]="ano",1,0) -> 0 | O4: =IF(Tabulka1[[#This Row],[Reklamace]]="ano",1,0) -> 1
A5: 831 | B5: 45299 | C5: Plzeň | D5: Pohovka Luxusní | E5: 14 | F5: 25000 | G5: 350000 | H5: 64268 | I5: ano | J5: 7 | K5: ano | L5: 1 | M5: individuální | N5: =IF(Tabulka1[[#This Row],[E-shop]]="ano",1,0) -> 1 | O5: =IF(Tabulka1[[#This Row],[Reklamace]]="ano",1,0) -> 1
A6: 200 | B6: 45744 | C6: Praha | D6: Pohovka Luxusní | E6: 13 | F6: 25000 | G6: 325000 | H6: 60718 | I6: ne | J6: 5 | K6: ano | L6: 4 | M6: individuální | N6: =IF(Tabulka1[[#This Row],[E-shop]]="ano",1,0) -> 0 | O6: =IF(Tabulka1[[#This Row],[Reklamace]]="ano",1,0) -> 1
A7: 352 | B7: 45667 | C7: Liberec | D7: Pohovka Luxusní | E7: 13 | F7: 25000 | G7: 325000 | H7: 71622 | I7: ne | J7: 8 | K7: ne | L7: 1 | M7: firemní | N7: =IF(Tabulka1[[#This Row],[E-shop]]="ano",1,0) -> 0 | O7: =IF(Tabulka1[[#This Row],[Reklamace]]="ano",1,0) -> 0
A8: 960 | B8: 45455 | C8: Brno | D8: Pohovka Luxusní | E8: 13 | F8: 25000 | G8: 325000 | H8: 77522 | I8: ano | J8: 6 | K8: ne | L8: 5 | M8: individuální | N8: =IF(Tabulka1[[#This Row],[E-shop]]="ano",1,0) -> 1 | O8: =IF(Tabulka1[[#This Row],[Reklamace]]="ano",1,0) -> 0
A9: 142 | B9: 45455 | C9: Olomouc | D9: Skříň Posuvná | E9: 14 | F9: 22000 | G9: 308000 | H9: 71706 | I9: ne | J9: 9 | K9: ano | L9: 1 | M9: individuální | N9: =IF(Tabulka1[[#This Row],[E-shop]]="ano",1,0) -> 0 | O9: =IF(Tabulka1[[#This Row],[Reklamace]]="ano",1,0) -> 1
A10: 567 | B10: 45431 | C10: Olomouc | D10: Skříň Posuvná | E10: 14 | F10: 22000 | G10: 308000 | H10: 74541 | I10: ne | J10: 8 | K10: ano | L10: 1 | M10: individuální | N10: =IF(Tabulka1[[#This Row],[E-shop]]="ano",1,0) -> 0 | O10: =IF(Tabulka1[[#This Row],[Reklamace]]="ano",1,0) -> 1
A11: 876 | B11: 45588 | C11: Ostrava | D11: Skříň Posuvná | E11: 14 | F11: 22000 | G11: 308000 | H11: 60100 | I11: ne | J11: 5 | K11: ano | L11: 3 | M11: firemní | N11: =IF(Tabulka1[[#This Row],[E-shop]]="ano",1,0) -> 0 | O11: =IF(Tabulka1[[#This Row],[Reklamace]]="ano",1,0) -> 1
A12: 903 | B12: 45474 | C12: Olomouc | D12: Skříň Posuvná | E12: 14 | F12: 22000 | G12: 308000 | H12: 53665 | I12: ano | J12: 4 | K12: ano | L12: 7 | M12: firemní | N12: =IF(Tabulka1[[#This Row],[E-shop]]="ano",1,0) -> 1 | O12: =IF(Tabulka1[[#This Row],[Reklamace]]="ano",1,0) -> 1
A13: 110 | B13: 45708 | C13: Olomouc | D13: Pohovka Luxusní | E13: 12 | F13: 25000 | G13: 300000 | H13: 58032 | I13: ano | J13: 5 | K13: ne | L13: 5 | M13: individuální | N13: =IF(Tabulka1[[#This Row],[E-shop]]="ano",1,0) -> 1 | O13: =IF(Tabulka1[[#This Row],[Reklamace]]="ano",1,0) -> 0
... A132: 758 | B132: 45542 | C132: Ostrava | D132: Pohovka Luxusní | E132: 6 | F132: 25000 | G132: 150000 | H132: 34373 | I132: ne | J132: 2 | K132: ne | L132: 6 | M132: individuální | N132: =IF(Tabulka1[[#This Row],[E-shop]]="ano",1,0) -> 0 | O132: =IF(Tabulka1[[#This Row],[Reklamace]]="ano",1,0) -> 0
A133: 10 | B133: 45412 | C133: Brno | D133: Skříň Šatní | E133: 8 | F133: 18000 | G133: 144000 | H133: =9754*4 -> 39016 | I133: ne | J133: 4 | K133: ne | L133: 5 | M133: individuální | N133: =IF(Tabulka1[[#This Row],[E-shop]]="ano",1,0) -> 0 | O133: =IF(Tabulka1[[#This Row],[Reklamace]]="ano",1,0) -> 0
A134: 76 | B134: 45639 | C134: Plzeň | D134: Skříň Šatní | E134: 8 | F134: 18000 | G134: 144000 | H134: 34917 | I134: ne | J134: 4 | K134: ano | L134: 6 | M134: individuální | N134: =IF(Tabulka1[[#This Row],[E-shop]]="ano",1,0) -> 0 | O134: =IF(Tabulka1[[#This Row],[Reklamace]]="ano",1,0) -> 1
A135: 123 | B135: 45649 | C135: Praha | D135: Křeslo Relax | E135: 12 | F135: 12000 | G135: 144000 | H135: 32024 | I135: ne | J135: 3 | K135: ano | L135: 6 | M135: individuální | N135: =IF(Tabulka1[[#This Row],[E-shop]]="ano",1,0) -> 0 | O135: =IF(Tabulka1[[#This Row],[Reklamace]]="ano",1,0) -> 1
A136: 189 | B136: 45811 | C136: Olomouc | D136: Komoda Bílá | E136: 12 | F136: 12000 | G136: 144000 | H136: 42925 | I136: ano | J136: 4 | K136: ne | L136: 4 | M136: individuální | N136: =IF(Tabulka1[[#This Row],[E-shop]]="ano",1,0) -> 1 | O136: =IF(Tabulka1[[#This Row],[Reklamace]]="ano",1,0) -> 0
A137: 385 | B137: 45825 | C137: Olomouc | D137: Komoda Bílá | E137: 12 | F137: 12000 | G137: 144000 | H137: 41138 | I137: ano | J137: 5 | K137: ne | L137: 6 | M137: individuální | N137: =IF(Tabulka1[[#This Row],[E-shop]]="ano",1,0) -> 1 | O137: =IF(Tabulka1[[#This Row],[Reklamace]]="ano",1,0) -> 0
A138: 424 | B138: 45806 | C138: Hradec Králové | D138: Komoda Bílá | E138: 12 | F138: 12000 | G138: 144000 | H138: 26288 | I138: ne | J138: 5 | K138: ne | L138: 6 | M138: individuální | N138: =IF(Tabulka1[[#This Row],[E-shop]]="ano",1,0) -> 0 | O138: =IF(Tabulka1[[#This Row],[Reklamace]]="ano",1,0) -> 0
A139: 526 | B139: 45938 | C139: Praha | D139: Komoda Bílá | E139: 12 | F139: 12000 | G139: 144000 | H139: 26809 | I139: ne | J139: 4 | K139: ano | L139: 4 | M139: individuální | N139: =IF(Tabulka1[[#This Row],[E-shop]]="ano",1,0) -> 0 | O139: =IF(Tabulka1[[#This Row],[Reklamace]]="ano",1,0) -> 1
A140: 649 | B140: 45428 | C140: Liberec | D140: Křeslo Relax | E140: 12 | F140: 12000 | G140: 144000 | H140: 43167 | I140: ano | J140: 6 | K140: ano | L140: 4 | M140: individuální | N140: =IF(Tabulka1[[#This Row],[E-shop]]="ano",1,0) -> 1 | O140: =IF(Tabulka1[[#This Row],[Reklamace]]="ano",1,0) -> 1
A141: 779 | B141: 45968 | C141: Praha | D141: Postel Dřevěná | E141: 12 | F141: 12000 | G141: 144000 | H141: 22259 | I141: ne | J141: 5 | K141: ne | L141: 3 | M141: individuální | N141: =IF(Tabulka1[[#This Row],[E-shop]]="ano",1,0) -> 0 | O141: =IF(Tabulka1[[#This Row],[Reklamace]]="ano",1,0) -> 0
A142: 910 | B142: 45308 | C142: Olomouc | D142: Postel Dřevěná | E142: 12 | F142: 12000 | G142: 144000 | H142: 22752 | I142: ano | J142: 8 | K142: ano | L142: 1 | M142: firemní | N142: =IF(Tabulka1[[#This Row],[E-shop]]="ano",1,0) -> 1 | O142: =IF(Tabulka1[[#This Row],[Reklamace]]="ano",1,0) -> 1
A143: 954 | B143: 45473 | C143: Olomouc | D143: Křeslo Relax | E143: 12 | F143: 12000 | G143: 144000 | H143: 32044 | I143: ne | J143: 7 | K143: ano | L143: 1 | M143: individuální | N143: =IF(Tabulka1[[#This Row],[E-shop]]="ano",1,0) -> 0 | O143: =IF(Tabulka1[[#This Row],[Reklamace]]="ano",1,0) -> 1
A144: 108 | B144: 45782 | C144: Olomouc | D144: Komoda Dubová | E144: 14 | F144: 10000 | G144: 140000 | H144: 32143 | I144: ne | J144: 5 | K144: ano | L144: 4 | M144: firemní | N144: =IF(Tabulka1[[#This Row],[E-shop]]="ano",1,0) -> 0 | O144: =IF(Tabulka1[[#This Row],[Reklamace]]="ano",1,0) -> 1
A145: 269 | B145: 45612 | C145: Hradec Králové | D145: Postel Čalouněná | E145: 7 | F145: 20000 | G145: 140000 | H145: 30862 | I145: ne | J145: 2 | K145: ano | L145: 7 | M145: individuální | N145: =IF(Tabulka1[[#This Row],[E-shop]]="ano",1,0) -> 0 | O145: =IF(Tabulka1[[#This Row],[Reklamace]]="ano",1,0) -> 1
... A1001: 927 | B1001: 45937 | C1001: Praha | D1001: Židle Elegant | E1001: 1 | F1001: 2500 | G1001: 2500 | H1001: 534 | I1001: ne | J1001: 2 | K1001: ne | L1001: 7 | M1001: firemní | N1001: =IF(Tabulka1[[#This Row],[E-shop]]="ano",1,0) -> 0 | O1001: =IF(Tabulka1[[#This Row],[Reklamace]]="ano",1,0) -> 0

Sheet deskriptiva
A1: Celkový zisk | B1: =SUM(dataset_prodejny_nabytek!H:H) -> 17903692
A2: Počet prodaných kusů | B2: =SUM(dataset_prodejny_nabytek!E:E) -> 7500
A3: Průměr prodaných kusů | B3: =AVERAGE(dataset_prodejny_nabytek!E:E) -> 7.5
A4: Rozptyl počtu prodaných kusů | B4: =_xlfn.VAR.P(dataset_prodejny_nabytek!E:E) -> 16.3 | C4: =_xlfn.VAR.S(dataset_prodejny_nabytek!E:E) -> 16.316316
A5: Směrodatná odchylka počtu prodaných kusů | B5: =_xlfn.STDEV.P(dataset_prodejny_nabytek!E:E) -> 4.0373258
A6: Nejmenší cena zboží [Kč] | B6: =MIN(dataset_prodejny_nabytek!F:F) -> 2500
A7: Největší zena zboží [Kč] | B7: =MAX(dataset_prodejny_nabytek!F:F) -> 25000
D11: =SQRT(B4) -> 4.0373258

Sheet ukol1
A1: Počet transakcí | B1: =COUNT(dataset_prodejny_nabytek!G:G) -> 1000
A2: Průměrný prodej | B2: =AVERAGE(dataset_prodejny_nabytek!G:G) -> 78816
A3: Median prodeje | B3: =MEDIAN(dataset_prodejny_nabytek!G:G) -> 60000
A4: Max prodej | B4: =MAX(dataset_prodejny_nabytek!G:G) -> 350000
A5: Min prodej | B5: =MIN(dataset_prodejny_nabytek!G:G) -> 2500
A6: Směrodatná odchylka | B6: =_xlfn.STDEV.P(dataset_prodejny_nabytek!G:G) -> 67177.512
A7: Rozptyl | B7: =_xlfn.VAR.P(dataset_prodejny_nabytek!G:G) -> 4512818144
A8: První kvartil | B8: =_xlfn.QUARTILE.INC(dataset_prodejny_nabytek!G:G,1) -> 30000
A9: Třetí kvartil | B9: =_xlfn.QUARTILE.INC(dataset_prodejny_nabytek!G:G,3) -> 108000
A10: 95 % kvantil | B10: =_xlfn.PERCENTILE.INC(dataset_prodejny_nabytek!G:G,0.95) -> 220000
A11: IQR | B11: =B9-B8 -> 78000
F26: {=COUNT} -> #NAME?

Sheet explorace
A1: Počet kusů x Celkový prodej | B1: =CORREL(dataset_prodejny_nabytek!E:E,dataset_prodejny_nabytek!G:G) -> 0.64046013
A2: Celkový prodej x Zisk | B2: =CORREL(dataset_prodejny_nabytek!G:G,dataset_prodejny_nabytek!H:H) -> 0.95989066

Sheet grafy
B3: Popisky řádků | C3: Součet z Celkovy_prodej
B4: Brno | C4: 11622500
B5: Hradec Králové | C5: 13275500
B6: Liberec | C6: 10231500
B7: Olomouc | C7: 12256500
B8: Ostrava | C8: 9878000
B9: Plzeň | C9: 10018500
B10: Praha | C10: 11533500
B11: Celkový součet | C11: 78816000
O24: Popisky řádků | P24: Součet z Celkovy_prodej
O25: Komoda Bílá | P25: 5532000
O26: Komoda Dubová | P26: 2690000
O27: Komoda Rustikální | P27: 1551000
O28: Konferenční stolek | P28: 1755000
O29: Konferenční stolek Sklo | P29: 2009000
O30: Křeslo Comfort | P30: 2200000
O31: Křeslo Relax | P31: 3792000
O32: Pohovka Luxusní | P32: 8475000
O33: Pohovka Modern | P33: 5115000
O34: Polička Nástěnná | P34: 591000
O35: Polička Rohová | P35: 1218000
O36: Postel Čalouněná | P36: 4180000
... O50: Celkový součet | P50: 78816000

Sheet ukol2
A1: Doba dodání x Spokojenost zákazníka | B1: =CORREL(dataset_prodejny_nabytek!J:J,dataset_prodejny_nabytek!L:L) -> -0.8849106
A2: Počet kusů x Reklamace | B2: =CORREL(dataset_prodejny_nabytek!E:E,dataset_prodejny_nabytek!O:O) -> 0.21206332
A3: Cena za kus x Celkový prodej | B3: =CORREL(dataset_prodejny_nabytek!F:F,dataset_prodejny_nabytek!G:G) -> 0.69659529
A4: Celkový prodej x Zisk | B4: =CORREL(dataset_prodejny_nabytek!G:G,dataset_prodejny_nabytek!H:H) -> 0.95989066
A5: Eshop x Celkový prodej | B5: =CORREL(dataset_prodejny_nabytek!N:N,dataset_prodejny_nabytek!G:G) -> 0.040025475
H17: Popisky řádků | I17: Součet z Celkovy_prodej
H18: ne | I18: 50426000
H19: ano | I19: 28390000
H20: Celkový součet | I20: 78816000
B31: Popisky řádků | C31: Počet z Reklamace | D31: Součet z dummy_reklamace
B32: Brno | C32: 147 | D32: 59
B33: Hradec Králové | C33: 160 | D33: 78
B34: Liberec | C34: 132 | D34: 42
B35: Olomouc | C35: 150 | D35: 63
B36: Ostrava | C36: 139 | D36: 63
B37: Plzeň | C37: 131 | D37: 54
B38: Praha | C38: 141 | D38: 57
B39: Celkový součet | C39: 1000 | D39: 416

Sheet diagnostika
A1: Prodejna | B1: Průměrná spokojenost | C1: Průměrná doba doručení
A2: {=_xlfn.UNIQUE(Tabulka1[Prodejna])} -> Praha | B2: {=AVERAGEIF(dataset_prodejny_nabytek!C:C,_xlfn.ANCHORARRAY(A2),dataset_prodejny_nabytek!L:L)} -> 4.5602837 | C2: {=AVERAGEIF(dataset_prodejny_nabytek!C:C,_xlfn.ANCHORARRAY(A2),dataset_prodejny_nabytek!J:J)} -> 4.8794326
A3: Plzeň | B3: 4.3587786 | C3: 5.1221374
A4: Brno | B4: 4.3741497 | C4: 5.2312925
A5: Liberec | B5: 4.4166667 | C5: 5.0075758
A6: Olomouc | B6: 4.4733333 | C6: 5.02
A7: Ostrava | B7: 4.1582734 | C7: 5.3165468
A8: Hradec Králové | B8: 4.325 | C8: 5.29375
B19: Popisky řádků | C19: Průměr z Spokojenost
B20: ne | C20: 5.4058219
B21: ano | C21: 2.9423077
B22: Celkový součet | C22: 4.381

Sheet datamining
A1: Počet z Cena_za_kus | B1: Popisky sloupců
A2: Popisky řádků | B2: Komoda Bílá | C2: Komoda Dubová | D2: Komoda Rustikální | E2: Konferenční stolek | F2: Konferenční stolek Sklo | G2: Křeslo Comfort | H2: Křeslo Relax | I2: Pohovka Luxusní | J2: Pohovka Modern | K2: Polička Nástěnná | L2: Polička Rohová | M2: Postel Čalouněná | N2: Postel Dětská | O2: Postel Dřevěná | P2: Regál Kovový | Q2: Skříň Posuvná | R2: Skříň Šatní | S2: Stojan na boty | T2: Stůl Jídelní | U2: Stůl Kulatý | V2: TV stolek | W2: TV stolek Modern | X2: Židle Elegant | Y2: Židle Herní | Z2: Židle Kovová | AA2: Celkový součet
A3: Brno | B3: 9 | C3: 6 | D3: 6 | E3: 8 | F3: 5 | G3: 6 | H3: 4 | I3: 7 | J3: 1 | K3: 5 | L3: 7 | M3: 4 | N3: 8 | O3: 8 | P3: 4 | Q3: 4 | R3: 9 | S3: 3 | T3: 4 | U3: 7 | V3: 9 | W3: 7 | X3: 6 | Y3: 5 | Z3: 5 | AA3: 147
A4: Hradec Králové | B4: 14 | C4: 4 | D4: 1 | E4: 8 | F4: 5 | G4: 6 | H4: 7 | I4: 8 | J4: 4 | K4: 3 | L4: 4 | M4: 8 | N4: 5 | O4: 9 | P4: 10 | Q4: 10 | R4: 6 | S4: 6 | T4: 7 | U4: 5 | V4: 6 | W4: 5 | X4: 7 | Y4: 6 | Z4: 6 | AA4: 160
A5: Liberec | B5: 9 | C5: 5 | D5: 5 | E5: 5 | F5: 8 | G5: 7 | H5: 10 | I5: 4 | J5: 4 | K5: 5 | L5: 4 | M5: 3 | N5: 9 | O5: 8 | P5: 3 | Q5: 7 | R5: 5 | S5: 5 | T5: 3 | U5: 6 | V5: 1 | W5: 6 | X5: 4 | Y5: 4 | Z5: 2 | AA5: 132
A6: Olomouc | B6: 8 | C6: 9 | D6: 3 | E6: 5 | F6: 8 | G6: 8 | H6: 5 | I6: 3 | J6: 4 | K6: 3 | L6: 8 | M6: 2 | N6: 7 | O6: 7 | P6: 4 | Q6: 9 | R6: 2 | S6: 6 | T6: 6 | U6: 5 | V6: 5 | W6: 8 | X6: 11 | Y6: 10 | Z6: 4 | AA6: 150
A7: Ostrava | B7: 9 | C7: 4 | D7: 4 | E7: 5 | F7: 2 | G7: 8 | H7: 9 | I7: 4 | J7: 10 | K7: 3 | L7: 5 | M7: 7 | N7: 6 | O7: 5 | P7: 7 | Q7: 8 | R7: 4 | S7: 6 | T7: 6 | U7: 2 | V7: 6 | W7: 4 | X7: 3 | Y7: 6 | Z7: 6 | AA7: 139
A8: Plzeň | B8: 5 | C8: 5 | D8: 3 | E8: 8 | F8: 5 | G8: 2 | H8: 4 | I8: 6 | J8: 7 | K8: 5 | L8: 7 | M8: 5 | N8: 5 | O8: 5 | P8: 11 | Q8: 2 | R8: 7 | S8: 2 | T8: 3 | U8: 3 | V8: 4 | W8: 4 | X8: 8 | Y8: 9 | Z8: 6 | AA8: 131
A9: Praha | B9: 7 | C9: 3 | E9: 7 | F9: 5 | G9: 4 | H9: 9 | I9: 10 | J9: 14 | K9: 5 | L9: 11 | M9: 4 | N9: 6 | O9: 3 | P9: 5 | Q9: 8 | R9: 7 | S9: 5 | T9: 3 | U9: 6 | V9: 3 | W9: 3 | X9: 6 | Y9: 5 | Z9: 2 | AA9: 141
A10: Celkový součet | B10: 61 | C10: 36 | D10: 22 | E10: 46 | F10: 38 | G10: 41 | H10: 48 | I10: 42 | J10: 44 | K10: 29 | L10: 46 | M10: 33 | N10: 46 | O10: 45 | P10: 44 | Q10: 48 | R10: 40 | S10: 33 | T10: 32 | U10: 34 | V10: 34 | W10: 37 | X10: 45 | Y10: 45 | Z10: 31 | AA10: 1000
A14: Popisky řádků | B14: Počet z Pocet_kusu | C14: Součet z dummy_reklamace
A15: Brno | B15: 147 | C15: 59 | E15: Počet kusů - prodejna | F15: Reklamace prodejny | G15: Míra reklamací
A16: Hradec Králové | B16: 160 | C16: 78 | D16: Brno | E16: 1120 | F16: 59 | G16: =F16/E16 -> 0.052678571
A17: Liberec | B17: 132 | C17: 42 | D17: Hradec Králové | E17: 1243 | F17: 78 | G17: =F17/E17 -> 0.062751408
A18: Olomouc | B18: 150 | C18: 63 | D18: Liberec | E18: 949 | F18: 42 | G18: =F18/E18 -> 0.044257113
A19: Ostrava | B19: 139 | C19: 63 | D19: Olomouc | E19: 1217 | F19: 63 | G19: =F19/E19 -> 0.051766639
A20: Plzeň | B20: 131 | C20: 54 | D20: Ostrava | E20: 931 | F20: 63 | G20: =F20/E20 -> 0.067669173
A21: Praha | B21: 141 | C21: 57 | D21: Plzeň | E21: 1005 | F21: 54 | G21: =F21/E21 -> 0.053731343
A22: Celkový součet | B22: 1000 | C22: 416 | D22: Praha | E22: 1035 | F22: 57 | G22: =F22/E22 -> 0.055072464
E23: =SUM(E16:E22) -> 7500 | F23: =SUM(F16:F22) -> 416 | G23: =F23/E23 -> 0.055466667
F29: =5/0 -> #DIV/0!
F30: =IFERROR(5/0,"Dělení nulou") -> Dělení nulou
E32: Ahoj jak to jde | F32: a b
E33: =TRIM(E32) -> Ahoj jak to jde | F33: =CLEAN(F32) -> a b

Sheet ukol3
H9: Popisky řádků | I9: Průměr z Spokojenost
H10: ne | I10: 4.3978659
H11: ano | I11: 4.3488372
H12: Celkový součet | I12: 4.381 | J12: ano | K12: ne
J13: {=_xlfn._xlws.FILTER(Tabulka1[Spokojenost],Tabulka1[E-shop]="ano")} -> 3 | K13: {=_xlfn._xlws.FILTER(Tabulka1[Spokojenost],Tabulka1[E-shop]="ne")} -> 1
J14: 1 | K14: 2
J15: 5 | K15: 4
J16: 7 | K16: 1
G17: firemní | H17: individuální | J17: 5 | K17: 1
D18: Popisky řádků | E18: Průměr z Spokojenost | G18: {=_xlfn._xlws.FILTER(Tabulka1[Spokojenost],Tabulka1[Typ_zakaznika]="firemní")} -> 1 | H18: {=_xlfn._xlws.FILTER(Tabulka1[Spokojenost],Tabulka1[Typ_zakaznika]="individuální")} -> 3 | J18: 2 | K18: 1
D19: firemní | E19: 4.5257732 | G19: 3 | H19: 1 | J19: 1 | K19: 3
D20: individuální | E20: 4.3461538 | G20: 7 | H20: 2 | J20: 1 | K20: 3
D21: Celkový součet | E21: 4.381 | G21: 2 | H21: 1 | J21: 4 | K21: 6
G22: 1 | H22: 4 | J22: 7 | K22: 4
G23: 1 | H23: 5 | J23: 7 | K23: 1
G24: 7 | H24: 1 | J24: 5 | K24: 8
G25: 3 | H25: 1 | J25: 3 | K25: 1
G26: 2 | H26: 5 | J26: 3 | K26: 3
G27: 6 | H27: 3 | J27: 4 | K27: 3
G28: 1 | H28: 6 | J28: 1 | K28: 2
G29: 3 | H29: 4 | J29: 1 | K29: 1
G30: 1 | H30: 1 | J30: 4 | K30: 4
G31: 1 | H31: 8 | J31: 6 | K31: 2
G32: 2 | H32: 1 | J32: 2 | K32: 1
G33: 3 | H33: 3 | J33: 1 | K33: 2
... G211: 7 | H211: 1 | J211: 8 | K211: 5
H212: 2 | J212: 6 | K212: 1
H213: 2 | J213: 6 | K213: 5
H214: 7 | J214: 7 | K214: 6
H215: 2 | J215: 6 | K215: 8
H216: 6 | J216: 7 | K216: 1
H217: 3 | J217: 4 | K217: 8
H218: 1 | J218: 5 | K218: 1
H219: 5 | J219: 4 | K219: 3
H220: 5 | J220: 2 | K220: 5
H221: 3 | J221: 6 | K221: 7
H222: 4 | J222: 5 | K222: 5
H223: 6 | J223: 3 | K223: 7
... H356: 3 | J356: 7 | K356: 2
H357: 6 | K357: 2
...
